Workbook

Sheet Настройки
A1: НАСТРОЙКИ ЗАРПЛАТЫ
A2: Сотрудник | B2: Ставка за смену, ₽ | C2: % от личной выручки | E2: Варианты смены
A3: Ирина Константиновна | B3: 3500 | C3: 0.05 | E3: Ирина
A4: Татьяна | B4: 3500 | C4: 0.05 | E4: Татьяна
E5: Обе
A6: Как работать
A7: 1 | B7: Меняйте только ставку и процент в строках сотрудников.
A8: 2 | B8: На листе «Касса» каждый день выбирайте смену и вносите продажи.
A9: 3 | B9: Наличка влияет на кассу; безнал — только на выручку.

Sheet Касса
A1: КАССА • ПРОДАЖИ • ЗАРПЛАТА • КОНТРОЛЬ
A2: Каждый день: Смена → продажи → расходы/внесения/изъятия → выданная ЗП → фактический остаток. Разница = Факт − Расчёт. Отрицательная разница означает недостачу учёта, но не доказывает кражу.
A3: Дата | B3: День недели | C3: Смена | D3: Остаток утром (нал) | E3: Наличка Ирина | F3: Безнал Ирина | G3: Итого Ирина | H3: Наличка Татьяна | I3: Безнал Татьяна | J3: Итого Татьяна | K3: Расход (нал) | L3: Внесено доп. в кассу (нал) | M3: Изъято из кассы (нал) | N3: ЗП Ирина (начислено) | O3: ЗП Татьяна (начислено) | P3: Выдано ЗП из кассы (нал) | Q3: Остаток вечером (расчёт) | R3: Остаток вечером (факт) | S3: Разница | T3: Статус | U3: Комментарий | V3: Проверка утра | W3: Выручка за все дни
A4: 46296 | B4: четверг | C4: Ирина | D4: 15050 | E4: 200 | F4: 35390 | G4: =IF(COUNTA(E4:F4)=0,"",SUM(E4:F4)) -> 35590 | J4: =IF(COUNTA(H4:I4)=0,"",SUM(H4:I4)) | N4: =IF(OR(C4="Ирина",C4="Обе"),Настройки!$B$3+IF(G4="",0,G4)*Настройки!$C$3,0) -> 5279.5 | O4: =IF(OR(C4="Татьяна",C4="Обе"),Настройки!$B$4+IF(J4="",0,J4)*Настройки!$C$4,0) -> 0 | Q4: =IF(A4="","",D4+E4+H4+L4-K4-P4-M4) -> 15250 | R4: 15250 | S4: =IF(ISNUMBER(R4),R4-Q4,"") -> 0 | T4: =IF(ISNUMBER(S4),IF(S4=0,"✅ ВСЁ ТОЧНО",IF(S4<0,"❌ НЕДОСТАЧА "&TEXT(ABS(S4),"#,##0")&" ₽","⚠️ ИЗЛИШЕК "&TEXT(S4,"#,##0")&" ₽")),"") -> ✅ ВСЁ ТОЧНО | V4: ="" | W4: =SUM(G4:G34)+SUM(J4:J34) -> 473950
A5: 46297 | B5: пятница | C5: Ирина | D5: 15250 | E5: 6300 | F5: 34545 | G5: =IF(COUNTA(E5:F5)=0,"",SUM(E5:F5)) -> 40845 | J5: =IF(COUNTA(H5:I5)=0,"",SUM(H5:I5)) | M5: 20000 | N5: =IF(OR(C5="Ирина",C5="Обе"),Настройки!$B$3+IF(G5="",0,G5)*Настройки!$C$3,0) -> 5542.25 | O5: =IF(OR(C5="Татьяна",C5="Обе"),Настройки!$B$4+IF(J5="",0,J5)*Настройки!$C$4,0) -> 0 | Q5: =IF(A5="","",D5+E5+H5+L5-K5-P5-M5) -> 1550 | R5: 1550 | S5: =IF(ISNUMBER(R5),R5-Q5,"") -> 0 | T5: =IF(ISNUMBER(S5),IF(S5=0,"✅ ВСЁ ТОЧНО",IF(S5<0,"❌ НЕДОСТАЧА "&TEXT(ABS(S5),"#,##0")&" ₽","⚠️ ИЗЛИШЕК "&TEXT(S5,"#,##0")&" ₽")),"") -> ✅ ВСЁ ТОЧНО | V5: =IF(OR(A5="",C5="",R4=""),"",IF(D5=R4,"✅ ОК","⚠️ ПРОВЕРИТЬ")) -> ✅ ОК | W5: =AVERAGE(G4:G34,J4:J34) -> 33853.571 | X5: =W5*31 -> 1049460.7
A6: 46298 | B6: суббота | C6: Татьяна | D6: 1550 | G6: =IF(COUNTA(E6:F6)=0,"",SUM(E6:F6)) | H6: 12000 | I6: 12400 | J6: =IF(COUNTA(H6:I6)=0,"",SUM(H6:I6)) -> 24400 | N6: =IF(OR(C6="Ирина",C6="Обе"),Настройки!$B$3+IF(G6="",0,G6)*Настройки!$C$3,0) -> 0 | O6: =IF(OR(C6="Татьяна",C6="Обе"),Настройки!$B$4+IF(J6="",0,J6)*Настройки!$C$4,0) -> 4720 | P6: 4720 | Q6: =IF(A6="","",D6+E6+H6+L6-K6-P6-M6) -> 8830 | R6: 8830 | S6: =IF(ISNUMBER(R6),R6-Q6,"") -> 0 | T6: =IF(ISNUMBER(S6),IF(S6=0,"✅ ВСЁ ТОЧНО",IF(S6<0,"❌ НЕДОСТАЧА "&TEXT(ABS(S6),"#,##0")&" ₽","⚠️ ИЗЛИШЕК "&TEXT(S6,"#,##0")&" ₽")),"") -> ✅ ВСЁ ТОЧНО | V6: =IF(OR(A6="",C6="",R5=""),"",IF(D6=R5,"✅ ОК","⚠️ ПРОВЕРИТЬ")) -> ✅ ОК
A7: 46299 | B7: воскресенье | C7: Татьяна | D7: 8830 | G7: =IF(COUNTA(E7:F7)=0,"",SUM(E7:F7)) | H7: 17150 | I7: 12400 | J7: =IF(COUNTA(H7:I7)=0,"",SUM(H7:I7)) -> 29550 | N7: =IF(OR(C7="Ирина",C7="Обе"),Настройки!$B$3+IF(G7="",0,G7)*Настройки!$C$3,0) -> 0 | O7: =IF(OR(C7="Татьяна",C7="Обе"),Настройки!$B$4+IF(J7="",0,J7)*Настройки!$C$4,0) -> 4977.5 | P7: 4980 | Q7: =IF(A7="","",D7+E7+H7+L7-K7-P7-M7) -> 21000 | R7: 21000 | S7: =IF(ISNUMBER(R7),R7-Q7,"") -> 0 | T7: =IF(ISNUMBER(S7),IF(S7=0,"✅ ВСЁ ТОЧНО",IF(S7<0,"❌ НЕДОСТАЧА "&TEXT(ABS(S7),"#,##0")&" ₽","⚠️ ИЗЛИШЕК "&TEXT(S7,"#,##0")&" ₽")),"") -> ✅ ВСЁ ТОЧНО | V7: =IF(OR(A7="",C7="",R6=""),"",IF(D7=R6,"✅ ОК","⚠️ ПРОВЕРИТЬ")) -> ✅ ОК
A8: 46300 | B8: понедельник | C8: Ирина | D8: 21000 | E8: 4050 | F8: 48740 | G8: =IF(COUNTA(E8:F8)=0,"",SUM(E8:F8)) -> 52790 | J8: =IF(COUNTA(H8:I8)=0,"",SUM(H8:I8)) | N8: =IF(OR(C8="Ирина",C8="Обе"),Настройки!$B$3+IF(G8="",0,G8)*Настройки!$C$3,0) -> 6139.5 | O8: =IF(OR(C8="Татьяна",C8="Обе"),Настройки!$B$4+IF(J8="",0,J8)*Настройки!$C$4,0) -> 0 | Q8: =IF(A8="","",D8+E8+H8+L8-K8-P8-M8) -> 25050 | R8: 25050 | S8: =IF(ISNUMBER(R8),R8-Q8,"") -> 0 | T8: =IF(ISNUMBER(S8),IF(S8=0,"✅ ВСЁ ТОЧНО",IF(S8<0,"❌ НЕДОСТАЧА "&TEXT(ABS(S8),"#,##0")&" ₽","⚠️ ИЗЛИШЕК "&TEXT(S8,"#,##0")&" ₽")),"") -> ✅ ВСЁ ТОЧНО | V8: =IF(OR(A8="",C8="",R7=""),"",IF(D8=R7,"✅ ОК","⚠️ ПРОВЕРИТЬ")) -> ✅ ОК
A9: 46301 | B9: вторник | C9: Ирина | D9: 25050 | E9: 2000 | F9: 32025 | G9: =IF(COUNTA(E9:F9)=0,"",SUM(E9:F9)) -> 34025 | J9: =IF(COUNTA(H9:I9)=0,"",SUM(H9:I9)) | K9: 6800 | N9: =IF(OR(C9="Ирина",C9="Обе"),Настройки!$B$3+IF(G9="",0,G9)*Настройки!$C$3,0) -> 5201.25 | O9: =IF(OR(C9="Татьяна",C9="Обе"),Настройки!$B$4+IF(J9="",0,J9)*Настройки!$C$4,0) -> 0 | Q9: =IF(A9="","",D9+E9+H9+L9-K9-P9-M9) -> 20250 | R9: 20250 | S9: =IF(ISNUMBER(R9),R9-Q9,"") -> 0 | T9: =IF(ISNUMBER(S9),IF(S9=0,"✅ ВСЁ ТОЧНО",IF(S9<0,"❌ НЕДОСТАЧА "&TEXT(ABS(S9),"#,##0")&" ₽","⚠️ ИЗЛИШЕК "&TEXT(S9,"#,##0")&" ₽")),"") -> ✅ ВСЁ ТОЧНО | U9: мешки - 750, дворник - 5000, доставка - 1050 за 05.10.26 | V9: =IF(OR(A9="",C9="",R8=""),"",IF(D9=R8,"✅ ОК","⚠️ ПРОВЕРИТЬ")) -> ✅ ОК
A10: 46302 | B10: среда | C10: Ирина | D10: 20250 | E10: 8500 | F10: 29915 | G10: =IF(COUNTA(E10:F10)=0,"",SUM(E10:F10)) -> 38415 | J10: =IF(COUNTA(H10:I10)=0,"",SUM(H10:I10)) | N10: =IF(OR(C10="Ирина",C10="Обе"),Настройки!$B$3+IF(G10="",0,G10)*Настройки!$C$3,0) -> 5420.75 | O10: =IF(OR(C10="Татьяна",C10="Обе"),Настройки!$B$4+IF(J10="",0,J10)*Настройки!$C$4,0) -> 0 | Q10: =IF(A10="","",D10+E10+H10+L10-K10-P10-M10) -> 28750 | R10: 28750 | S10: =IF(ISNUMBER(R10),R10-Q10,"") -> 0 | T10: =IF(ISNUMBER(S10),IF(S10=0,"✅ ВСЁ ТОЧНО",IF(S10<0,"❌ НЕДОСТАЧА "&TEXT(ABS(S10),"#,##0")&" ₽","⚠️ ИЗЛИШЕК "&TEXT(S10,"#,##0")&" ₽")),"") -> ✅ ВСЁ ТОЧНО | V10: =IF(OR(A10="",C10="",R9=""),"",IF(D10=R9,"✅ ОК","⚠️ ПРОВЕРИТЬ")) -> ✅ ОК
A11: 46303 | B11: четверг | C11: Ирина | D11: 28750 | E11: 8030 | F11: 26050 | G11: =IF(COUNTA(E11:F11)=0,"",SUM(E11:F11)) -> 34080 | J11: =IF(COUNTA(H11:I11)=0,"",SUM(H11:I11)) | K11: 9800 | M11: 25000 | N11: =IF(OR(C11="Ирина",C11="Обе"),Настройки!$B$3+IF(G11="",0,G11)*Настройки!$C$3,0) -> 5204 | O11: =IF(OR(C11="Татьяна",C11="Обе"),Настройки!$B$4+IF(J11="",0,J11)*Настройки!$C$4,0) -> 0 | Q11: =IF(A11="","",D11+E11+H11+L11-K11-P11-M11) -> 1980 | R11: 1980 | S11: =IF(ISNUMBER(R11),R11-Q11,"") -> 0 | T11: =IF(ISNUMBER(S11),IF(S11=0,"✅ ВСЁ ТОЧНО",IF(S11<0,"❌ НЕДОСТАЧА "&TEXT(ABS(S11),"#,##0")&" ₽","⚠️ ИЗЛИШЕК "&TEXT(S11,"#,##0")&" ₽")),"") -> ✅ ВСЁ ТОЧНО | U11: георгин 70 шт - 9800 | V11: =IF(OR(A11="",C11="",R10=""),"",IF(D11=R10,"✅ ОК","⚠️ ПРОВЕРИТЬ")) -> ✅ ОК
A12: 46304 | B12: пятница | C12: Татьяна | D12: 1980 | G12: =IF(COUNTA(E12:F12)=0,"",SUM(E12:F12)) | H12: 7400 | I12: 17380 | J12: =IF(COUNTA(H12:I12)=0,"",SUM(H12:I12)) -> 24780 | K12: 950 | M12: 825 | N12: =IF(OR(C12="Ирина",C12="Обе"),Настройки!$B$3+IF(G12="",0,G12)*Настройки!$C$3,0) -> 0 | O12: =IF(OR(C12="Татьяна",C12="Обе"),Настройки!$B$4+IF(J12="",0,J12)*Настройки!$C$4,0) -> 4739 | P12: 4700 | Q12: =IF(A12="","",D12+E12+H12+L12-K12-P12-M12) -> 2905 | R12: 2905 | S12: =IF(ISNUMBER(R12),R12-Q12,"") -> 0 | T12: =IF(ISNUMBER(S12),IF(S12=0,"✅ ВСЁ ТОЧНО",IF(S12<0,"❌ НЕДОСТАЧА "&TEXT(ABS(S12),"#,##0")&" ₽","⚠️ ИЗЛИШЕК "&TEXT(S12,"#,##0")&" ₽")),"") -> ✅ ВСЁ ТОЧНО | U12: курьер - 950, скидка букет тюльпанов 825 | V12: =IF(OR(A12="",C12="",R11=""),"",IF(D12=R11,"✅ ОК","⚠️ ПРОВЕРИТЬ")) -> ✅ ОК
A13: 46305 | B13: суббота | C13: Татьяна | D13: 2905 | G13: =IF(COUNTA(E13:F13)=0,"",SUM(E13:F13)) | H13: 5550 | I13: 34545 | J13: =IF(COUNTA(H13:I13)=0,"",SUM(H13:I13)) -> 40095 | N13: =IF(OR(C13="Ирина",C13="Обе"),Настройки!$B$3+IF(G13="",0,G13)*Настройки!$C$3,0) -> 0 | O13: =IF(OR(C13="Татьяна",C13="Обе"),Настройки!$B$4+IF(J13="",0,J13)*Настройки!$C$4,0) -> 5504.75 | P13: 5500 | Q13: =IF(A13="","",D13+E13+H13+L13-K13-P13-M13) -> 2955 | R13: 2955 | S13: =IF(ISNUMBER(R13),R13-Q13,"") -> 0 | T13: =IF(ISNUMBER(S13),IF(S13=0,"✅ ВСЁ ТОЧНО",IF(S13<0,"❌ НЕДОСТАЧА "&TEXT(ABS(S13),"#,##0")&" ₽","⚠️ ИЗЛИШЕК "&TEXT(S13,"#,##0")&" ₽")),"") -> ✅ ВСЁ ТОЧНО | V13: =IF(OR(A13="",C13="",R12=""),"",IF(D13=R12,"✅ ОК","⚠️ ПРОВЕРИТЬ")) -> ✅ ОК
A14: 46306 | B14: воскресенье | C14: Ирина | D14: 2955 | E14: 3430 | F14: 23455 | G14: =IF(COUNTA(E14:F14)=0,"",SUM(E14:F14)) -> 26885 | J14: =IF(COUNTA(H14:I14)=0,"",SUM(H14:I14)) | N14: =IF(OR(C14="Ирина",C14="Обе"),Настройки!$B$3+IF(G14="",0,G14)*Настройки!$C$3,0) -> 4844.25 | O14: =IF(OR(C14="Татьяна",C14="Обе"),Настройки!$B$4+IF(J14="",0,J14)*Настройки!$C$4,0) -> 0 | P14: 5000 | Q14: =IF(A14="","",D14+E14+H14+L14-K14-P14-M14) -> 1385 | R14: 1335 | S14: =IF(ISNUMBER(R14),R14-Q14,"") -> -50 | T14: =IF(ISNUMBER(S14),IF(S14=0,"✅ ВСЁ ТОЧНО",IF(S14<0,"❌ НЕДОСТАЧА "&TEXT(ABS(S14),"#,##0")&" ₽","⚠️ ИЗЛИШЕК "&TEXT(S14,"#,##0")&" ₽")),"") -> ❌ НЕДОСТАЧА 50,0 ₽ | V14: =IF(OR(A14="",C14="",R13=""),"",IF(D14=R13,"✅ ОК","⚠️ ПРОВЕРИТЬ")) -> ✅ ОК
A15: 46307 | B15: понедельник | C15: Ирина | D15: 2905 | E15: 0 | F15: 31250 | G15: =IF(COUNTA(E15:F15)=0,"",SUM(E15:F15)) -> 31250 | J15: =IF(COUNTA(H15:I15)=0,"",SUM(H15:I15)) | N15: =IF(OR(C15="Ирина",C15="Обе"),Настройки!$B$3+IF(G15="",0,G15)*Настройки!$C$3,0) -> 5062.5 | O15: =IF(OR(C15="Татьяна",C15="Обе"),Настройки!$B$4+IF(J15="",0,J15)*Настройки!$C$4,0) -> 0 | Q15: =IF(A15="","",D15+E15+H15+L15-K15-P15-M15) -> 2905 | R15: 2905 | S15: =IF(ISNUMBER(R15),R15-Q15,"") -> 0 | T15: =IF(ISNUMBER(S15),IF(S15=0,"✅ ВСЁ ТОЧНО",IF(S15<0,"❌ НЕДОСТАЧА "&TEXT(ABS(S15),"#,##0")&" ₽","⚠️ ИЗЛИШЕК "&TEXT(S15,"#,##0")&" ₽")),"") -> ✅ ВСЁ ТОЧНО | V15: =IF(OR(A15="",C15="",R14=""),"",IF(D15=R14,"✅ ОК","⚠️ ПРОВЕРИТЬ")) -> ⚠️ ПРОВЕРИТЬ
A16: 46308 | B16: вторник | C16: Ирина | D16: 2905 | E16: 13020 | F16: 27618 | G16: =IF(COUNTA(E16:F16)=0,"",SUM(E16:F16)) -> 40638 | J16: =IF(COUNTA(H16:I16)=0,"",SUM(H16:I16)) | N16: =IF(OR(C16="Ирина",C16="Обе"),Настройки!$B$3+IF(G16="",0,G16)*Настройки!$C$3,0) -> 5531.9 | O16: =IF(OR(C16="Татьяна",C16="Обе"),Настройки!$B$4+IF(J16="",0,J16)*Настройки!$C$4,0) -> 0 | P16: 5550 | Q16: =IF(A16="","",D16+E16+H16+L16-K16-P16-M16) -> 10375 | R16: 15925 | S16: =IF(ISNUMBER(R16),R16-Q16,"") -> 5550 | T16: =IF(ISNUMBER(S16),IF(S16=0,"✅ ВСЁ ТОЧНО",IF(S16<0,"❌ НЕДОСТАЧА "&TEXT(ABS(S16),"#,##0")&" ₽","⚠️ ИЗЛИШЕК "&TEXT(S16,"#,##0")&" ₽")),"") -> ⚠️ ИЗЛИШЕК 5550,0 ₽ | V16: =IF(OR(A16="",C16="",R15=""),"",IF(D16=R15,"✅ ОК","⚠️ ПРОВЕРИТЬ")) -> ✅ ОК
A17: 46309 | B17: среда | C17: Ирина | D17: 15925 | E17: 0 | F17: 20607 | G17: =IF(COUNTA(E17:F17)=0,"",SUM(E17:F17)) -> 20607 | J17: =IF(COUNTA(H17:I17)=0,"",SUM(H17:I17)) | N17: =IF(OR(C17="Ирина",C17="Обе"),Настройки!$B$3+IF(G17="",0,G17)*Настройки!$C$3,0) -> 4530.35 | O17: =IF(OR(C17="Татьяна",C17="Обе"),Настройки!$B$4+IF(J17="",0,J17)*Настройки!$C$4,0) -> 0 | Q17: =IF(A17="","",D17+E17+H17+L17-K17-P17-M17) -> 15925 | R17: 15925 | S17: =IF(ISNUMBER(R17),R17-Q17,"") -> 0 | T17: =IF(ISNUMBER(S17),IF(S17=0,"✅ ВСЁ ТОЧНО",IF(S17<0,"❌ НЕДОСТАЧА "&TEXT(ABS(S17),"#,##0")&" ₽","⚠️ ИЗЛИШЕК "&TEXT(S17,"#,##0")&" ₽")),"") -> ✅ ВСЁ ТОЧНО | V17: =IF(OR(A17="",C17="",R16=""),"",IF(D17=R16,"✅ ОК","⚠️ ПРОВЕРИТЬ")) -> ✅ ОК
A18: 46310 | B18: четверг | C18: Ирина | D18: 15925 | G18: =IF(COUNTA(E18:F18)=0,"",SUM(E18:F18)) | J18: =IF(COUNTA(H18:I18)=0,"",SUM(H18:I18)) | N18: =IF(OR(C18="Ирина",C18="Обе"),Настройки!$B$3+IF(G18="",0,G18)*Настройки!$C$3,0) -> 3500 | O18: =IF(OR(C18="Татьяна",C18="Обе"),Настройки!$B$4+IF(J18="",0,J18)*Настройки!$C$4,0) -> 0 | Q18: =IF(A18="","",D18+E18+H18+L18-K18-P18-M18) -> 15925 | S18: =IF(ISNUMBER(R18),R18-Q18,"") | T18: =IF(ISNUMBER(S18),IF(S18=0,"✅ ВСЁ ТОЧНО",IF(S18<0,"❌ НЕДОСТАЧА "&TEXT(ABS(S18),"#,##0")&" ₽","⚠️ ИЗЛИШЕК "&TEXT(S18,"#,##0")&" ₽")),"") | V18: =IF(OR(A18="",C18="",R17=""),"",IF(D18=R17,"✅ ОК","⚠️ ПРОВЕРИТЬ")) -> ✅ ОК
A19: 46311 | B19: пятница | C19: Татьяна | G19: =IF(COUNTA(E19:F19)=0,"",SUM(E19:F19)) | J19: =IF(COUNTA(H19:I19)=0,"",SUM(H19:I19)) | N19: =IF(OR(C19="Ирина",C19="Обе"),Настройки!$B$3+IF(G19="",0,G19)*Настройки!$C$3,0) -> 0 | O19: =IF(OR(C19="Татьяна",C19="Обе"),Настройки!$B$4+IF(J19="",0,J19)*Настройки!$C$4,0) -> 3500 | Q19: =IF(A19="","",D19+E19+H19+L19-K19-P19-M19) -> 0 | S19: =IF(ISNUMBER(R19),R19-Q19,"") | T19: =IF(ISNUMBER(S19),IF(S19=0,"✅ ВСЁ ТОЧНО",IF(S19<0,"❌ НЕДОСТАЧА "&TEXT(ABS(S19),"#,##0")&" ₽","⚠️ ИЗЛИШЕК "&TEXT(S19,"#,##0")&" ₽")),"") | V19: =IF(OR(A19="",C19="",R18=""),"",IF(D19=R18,"✅ ОК","⚠️ ПРОВЕРИТЬ"))
A20: 46312 | B20: суббота | C20: Ирина | G20: =IF(COUNTA(E20:F20)=0,"",SUM(E20:F20)) | J20: =IF(COUNTA(H20:I20)=0,"",SUM(H20:I20)) | N20: =IF(OR(C20="Ирина",C20="Обе"),Настройки!$B$3+IF(G20="",0,G20)*Настройки!$C$3,0) -> 3500 | O20: =IF(OR(C20="Татьяна",C20="Обе"),Настройки!$B$4+IF(J20="",0,J20)*Настройки!$C$4,0) -> 0 | Q20: =IF(A20="","",D20+E20+H20+L20-K20-P20-M20) -> 0 | S20: =IF(ISNUMBER(R20),R20-Q20,"") | T20: =IF(ISNUMBER(S20),IF(S20=0,"✅ ВСЁ ТОЧНО",IF(S20<0,"❌ НЕДОСТАЧА "&TEXT(ABS(S20),"#,##0")&" ₽","⚠️ ИЗЛИШЕК "&TEXT(S20,"#,##0")&" ₽")),"") | V20: =IF(OR(A20="",C20="",R19=""),"",IF(D20=R19,"✅ ОК","⚠️ ПРОВЕРИТЬ"))
A21: 46313 | B21: воскресенье | C21: Ирина | G21: =IF(COUNTA(E21:F21)=0,"",SUM(E21:F21)) | J21: =IF(COUNTA(H21:I21)=0,"",SUM(H21:I21)) | N21: =IF(OR(C21="Ирина",C21="Обе"),Настройки!$B$3+IF(G21="",0,G21)*Настройки!$C$3,0) -> 3500 | O21: =IF(OR(C21="Татьяна",C21="Обе"),Настройки!$B$4+IF(J21="",0,J21)*Настройки!$C$4,0) -> 0 | Q21: =IF(A21="","",D21+E21+H21+L21-K21-P21-M21) -> 0 | S21: =IF(ISNUMBER(R21),R21-Q21,"") | T21: =IF(ISNUMBER(S21),IF(S21=0,"✅ ВСЁ ТОЧНО",IF(S21<0,"❌ НЕДОСТАЧА "&TEXT(ABS(S21),"#,##0")&" ₽","⚠️ ИЗЛИШЕК "&TEXT(S21,"#,##0")&" ₽")),"") | V21: =IF(OR(A21="",C21="",R20=""),"",IF(D21=R20,"✅ ОК","⚠️ ПРОВЕРИТЬ"))
A22: 46314 | B22: понедельник | C22: Ирина | G22: =IF(COUNTA(E22:F22)=0,"",SUM(E22:F22)) | J22: =IF(COUNTA(H22:I22)=0,"",SUM(H22:I22)) | N22: =IF(OR(C22="Ирина",C22="Обе"),Настройки!$B$3+IF(G22="",0,G22)*Настройки!$C$3,0) -> 3500 | O22: =IF(OR(C22="Татьяна",C22="Обе"),Настройки!$B$4+IF(J22="",0,J22)*Настройки!$C$4,0) -> 0 | Q22: =IF(A22="","",D22+E22+H22+L22-K22-P22-M22) -> 0 | S22: =IF(ISNUMBER(R22),R22-Q22,"") | T22: =IF(ISNUMBER(S22),IF(S22=0,"✅ ВСЁ ТОЧНО",IF(S22<0,"❌ НЕДОСТАЧА "&TEXT(ABS(S22),"#,##0")&" ₽","⚠️ ИЗЛИШЕК "&TEXT(S22,"#,##0")&" ₽")),"") | V22: =IF(OR(A22="",C22="",R21=""),"",IF(D22=R21,"✅ ОК","⚠️ ПРОВЕРИТЬ"))
A23: 46315 | B23: вторник | C23: Ирина | G23: =IF(COUNTA(E23:F23)=0,"",SUM(E23:F23)) | J23: =IF(COUNTA(H23:I23)=0,"",SUM(H23:I23)) | N23: =IF(OR(C23="Ирина",C23="Обе"),Настройки!$B$3+IF(G23="",0,G23)*Настройки!$C$3,0) -> 3500 | O23: =IF(OR(C23="Татьяна",C23="Обе"),Настройки!$B$4+IF(J23="",0,J23)*Настройки!$C$4,0) -> 0 | Q23: =IF(A23="","",D23+E23+H23+L23-K23-P23-M23) -> 0 | S23: =IF(ISNUMBER(R23),R23-Q23,"") | T23: =IF(ISNUMBER(S23),IF(S23=0,"✅ ВСЁ ТОЧНО",IF(S23<0,"❌ НЕДОСТАЧА "&TEXT(ABS(S23),"#,##0")&" ₽","⚠️ ИЗЛИШЕК "&TEXT(S23,"#,##0")&" ₽")),"") | V23: =IF(OR(A23="",C23="",R22=""),"",IF(D23=R22,"✅ ОК","⚠️ ПРОВЕРИТЬ"))
A24: 46316 | B24: среда | C24: Ирина | G24: =IF(COUNTA(E24:F24)=0,"",SUM(E24:F24)) | J24: =IF(COUNTA(H24:I24)=0,"",SUM(H24:I24)) | N24: =IF(OR(C24="Ирина",C24="Обе"),Настройки!$B$3+IF(G24="",0,G24)*Настройки!$C$3,0) -> 3500 | O24: =IF(OR(C24="Татьяна",C24="Обе"),Настройки!$B$4+IF(J24="",0,J24)*Настройки!$C$4,0) -> 0 | Q24: =IF(A24="","",D24+E24+H24+L24-K24-P24-M24) -> 0 | S24: =IF(ISNUMBER(R24),R24-Q24,"") | T24: =IF(ISNUMBER(S24),IF(S24=0,"✅ ВСЁ ТОЧНО",IF(S24<0,"❌ НЕДОСТАЧА "&TEXT(ABS(S24),"#,##0")&" ₽","⚠️ ИЗЛИШЕК "&TEXT(S24,"#,##0")&" ₽")),"") | V24: =IF(OR(A24="",C24="",R23=""),"",IF(D24=R23,"✅ ОК","⚠️ ПРОВЕРИТЬ"))
A25: 46317 | B25: четверг | C25: Ирина | G25: =IF(COUNTA(E25:F25)=0,"",SUM(E25:F25)) | J25: =IF(COUNTA(H25:I25)=0,"",SUM(H25:I25)) | N25: =IF(OR(C25="Ирина",C25="Обе"),Настройки!$B$3+IF(G25="",0,G25)*Настройки!$C$3,0) -> 3500 | O25: =IF(OR(C25="Татьяна",C25="Обе"),Настройки!$B$4+IF(J25="",0,J25)*Настройки!$C$4,0) -> 0 | Q25: =IF(A25="","",D25+E25+H25+L25-K25-P25-M25) -> 0 | S25: =IF(ISNUMBER(R25),R25-Q25,"") | T25: =IF(ISNUMBER(S25),IF(S25=0,"✅ ВСЁ ТОЧНО",IF(S25<0,"❌ НЕДОСТАЧА "&TEXT(ABS(S25),"#,##0")&" ₽","⚠️ ИЗЛИШЕК "&TEXT(S25,"#,##0")&" ₽")),"") | V25: =IF(OR(A25="",C25="",R24=""),"",IF(D25=R24,"✅ ОК","⚠️ ПРОВЕРИТЬ"))
A26: 46318 | B26: пятница | C26: Ирина | G26: =IF(COUNTA(E26:F26)=0,"",SUM(E26:F26)) | J26: =IF(COUNTA(H26:I26)=0,"",SUM(H26:I26)) | N26: =IF(OR(C26="Ирина",C26="Обе"),Настройки!$B$3+IF(G26="",0,G26)*Настройки!$C$3,0) -> 3500 | O26: =IF(OR(C26="Татьяна",C26="Обе"),Настройки!$B$4+IF(J26="",0,J26)*Настройки!$C$4,0) -> 0 | Q26: =IF(A26="","",D26+E26+H26+L26-K26-P26-M26) -> 0 | S26: =IF(ISNUMBER(R26),R26-Q26,"") | T26: =IF(ISNUMBER(S26),IF(S26=0,"✅ ВСЁ ТОЧНО",IF(S26<0,"❌ НЕДОСТАЧА "&TEXT(ABS(S26),"#,##0")&" ₽","⚠️ ИЗЛИШЕК "&TEXT(S26,"#,##0")&" ₽")),"") | V26: =IF(OR(A26="",C26="",R25=""),"",IF(D26=R25,"✅ ОК","⚠️ ПРОВЕРИТЬ"))
A27: 46319 | B27: суббота | C27: Ирина | G27: =IF(COUNTA(E27:F27)=0,"",SUM(E27:F27)) | J27: =IF(COUNTA(H27:I27)=0,"",SUM(H27:I27)) | N27: =IF(OR(C27="Ирина",C27="Обе"),Настройки!$B$3+IF(G27="",0,G27)*Настройки!$C$3,0) -> 3500 | O27: =IF(OR(C27="Татьяна",C27="Обе"),Настройки!$B$4+IF(J27="",0,J27)*Настройки!$C$4,0) -> 0 | Q27: =IF(A27="","",D27+E27+H27+L27-K27-P27-M27) -> 0 | S27: =IF(ISNUMBER(R27),R27-Q27,"") | T27: =IF(ISNUMBER(S27),IF(S27=0,"✅ ВСЁ ТОЧНО",IF(S27<0,"❌ НЕДОСТАЧА "&TEXT(ABS(S27),"#,##0")&" ₽","⚠️ ИЗЛИШЕК "&TEXT(S27,"#,##0")&" ₽")),"") | V27: =IF(OR(A27="",C27="",R26=""),"",IF(D27=R26,"✅ ОК","⚠️ ПРОВЕРИТЬ"))
A28: 46320 | B28: воскресенье | C28: Ирина | G28: =IF(COUNTA(E28:F28)=0,"",SUM(E28:F28)) | J28: =IF(COUNTA(H28:I28)=0,"",SUM(H28:I28)) | N28: =IF(OR(C28="Ирина",C28="Обе"),Настройки!$B$3+IF(G28="",0,G28)*Настройки!$C$3,0) -> 3500 | O28: =IF(OR(C28="Татьяна",C28="Обе"),Настройки!$B$4+IF(J28="",0,J28)*Настройки!$C$4,0) -> 0 | Q28: =IF(A28="","",D28+E28+H28+L28-K28-P28-M28) -> 0 | S28: =IF(ISNUMBER(R28),R28-Q28,"") | T28: =IF(ISNUMBER(S28),IF(S28=0,"✅ ВСЁ ТОЧНО",IF(S28<0,"❌ НЕДОСТАЧА "&TEXT(ABS(S28),"#,##0")&" ₽","⚠️ ИЗЛИШЕК "&TEXT(S28,"#,##0")&" ₽")),"") | V28: =IF(OR(A28="",C28="",R27=""),"",IF(D28=R27,"✅ ОК","⚠️ ПРОВЕРИТЬ"))
A29: 46321 | B29: понедельник | C29: Ирина | G29: =IF(COUNTA(E29:F29)=0,"",SUM(E29:F29)) | J29: =IF(COUNTA(H29:I29)=0,"",SUM(H29:I29)) | N29: =IF(OR(C29="Ирина",C29="Обе"),Настройки!$B$3+IF(G29="",0,G29)*Настройки!$C$3,0) -> 3500 | O29: =IF(OR(C29="Татьяна",C29="Обе"),Настройки!$B$4+IF(J29="",0,J29)*Настройки!$C$4,0) -> 0 | Q29: =IF(A29="","",D29+E29+H29+L29-K29-P29-M29) -> 0 | S29: =IF(ISNUMBER(R29),R29-Q29,"") | T29: =IF(ISNUMBER(S29),IF(S29=0,"✅ ВСЁ ТОЧНО",IF(S29<0,"❌ НЕДОСТАЧА "&TEXT(ABS(S29),"#,##0")&" ₽","⚠️ ИЗЛИШЕК "&TEXT(S29,"#,##0")&" ₽")),"") | V29: =IF(OR(A29="",C29="",R28=""),"",IF(D29=R28,"✅ ОК","⚠️ ПРОВЕРИТЬ"))
A30: 46322 | B30: вторник | C30: Татьяна | G30: =IF(COUNTA(E30:F30)=0,"",SUM(E30:F30)) | J30: =IF(COUNTA(H30:I30)=0,"",SUM(H30:I30)) | N30: =IF(OR(C30="Ирина",C30="Обе"),Настройки!$B$3+IF(G30="",0,G30)*Настройки!$C$3,0) -> 0 | O30: =IF(OR(C30="Татьяна",C30="Обе"),Настройки!$B$4+IF(J30="",0,J30)*Настройки!$C$4,0) -> 3500 | Q30: =IF(A30="","",D30+E30+H30+L30-K30-P30-M30) -> 0 | S30: =IF(ISNUMBER(R30),R30-Q30,"") | T30: =IF(ISNUMBER(S30),IF(S30=0,"✅ ВСЁ ТОЧНО",IF(S30<0,"❌ НЕДОСТАЧА "&TEXT(ABS(S30),"#,##0")&" ₽","⚠️ ИЗЛИШЕК "&TEXT(S30,"#,##0")&" ₽")),"") | V30: =IF(OR(A30="",C30="",R29=""),"",IF(D30=R29,"✅ ОК","⚠️ ПРОВЕРИТЬ"))
... A34: 46326 | B34: суббота | C34: Ирина | G34: =IF(COUNTA(E34:F34)=0,"",SUM(E34:F34)) | J34: =IF(COUNTA(H34:I34)=0,"",SUM(H34:I34)) | N34: =IF(OR(C34="Ирина",C34="Обе"),Настройки!$B$3+IF(G34="",0,G34)*Настройки!$C$3,0) -> 3500 | O34: =IF(OR(C34="Татьяна",C34="Обе"),Настройки!$B$4+IF(J34="",0,J34)*Настройки!$C$4,0) -> 0 | Q34: =IF(A34="","",D34+E34+H34+L34-K34-P34-M34) -> 0 | S34: =IF(ISNUMBER(R34),R34-Q34,"") | T34: =IF(ISNUMBER(S34),IF(S34=0,"✅ ВСЁ ТОЧНО",IF(S34<0,"❌ НЕДОСТАЧА "&TEXT(ABS(S34),"#,##0")&" ₽","⚠️ ИЗЛИШЕК "&TEXT(S34,"#,##0")&" ₽")),"") | V34: =IF(OR(A34="",C34="",R33=""),"",IF(D34=R33,"✅ ОК","⚠️ ПРОВЕРИТЬ"))
B35: =IF(A35="","",CHOOSE(WEEKDAY(A35,2),"понедельник","вторник","среда","четверг","пятница","суббота","воскресенье")) | G35: =IF(COUNTA(E35:F35)=0,"",SUM(E35:F35)) | J35: =IF(COUNTA(H35:I35)=0,"",SUM(H35:I35)) | N35: =IF(OR(C35="Ирина",C35="Обе"),Настройки!$B$3+IF(G35="",0,G35)*Настройки!$C$3,0) -> 0 | O35: =IF(OR(C35="Татьяна",C35="Обе"),Настройки!$B$4+IF(J35="",0,J35)*Настройки!$C$4,0) -> 0 | Q35: =IF(A35="","",D35+E35+H35+L35-K35-P35-M35) | S35: =IF(ISNUMBER(R35),R35-Q35,"") | T35: =IF(ISNUMBER(S35),IF(S35=0,"✅ ВСЁ ТОЧНО",IF(S35<0,"❌ НЕДОСТАЧА "&TEXT(ABS(S35),"#,##0")&" ₽","⚠️ ИЗЛИШЕК "&TEXT(S35,"#,##0")&" ₽")),"") | V35: =IF(OR(A35="",C35="",R34=""),"",IF(D35=R34,"✅ ОК","⚠️ ПРОВЕРИТЬ"))
B36: =IF(A36="","",CHOOSE(WEEKDAY(A36,2),"понедельник","вторник","среда","четверг","пятница","суббота","воскресенье")) | G36: =IF(COUNTA(E36:F36)=0,"",SUM(E36:F36)) | J36: =IF(COUNTA(H36:I36)=0,"",SUM(H36:I36)) | N36: =IF(OR(C36="Ирина",C36="Обе"),Настройки!$B$3+IF(G36="",0,G36)*Настройки!$C$3,0) -> 0 | O36: =IF(OR(C36="Татьяна",C36="Обе"),Настройки!$B$4+IF(J36="",0,J36)*Настройки!$C$4,0) -> 0 | Q36: =IF(A36="","",D36+E36+H36+L36-K36-P36-M36) | S36: =IF(ISNUMBER(R36),R36-Q36,"") | T36: =IF(ISNUMBER(S36),IF(S36=0,"✅ ВСЁ ТОЧНО",IF(S36<0,"❌ НЕДОСТАЧА "&TEXT(ABS(S36),"#,##0")&" ₽","⚠️ ИЗЛИШЕК "&TEXT(S36,"#,##0")&" ₽")),"") | V36: =IF(OR(A36="",C36="",R35=""),"",IF(D36=R35,"✅ ОК","⚠️ ПРОВЕРИТЬ"))
B37: =IF(A37="","",CHOOSE(WEEKDAY(A37,2),"понедельник","вторник","среда","четверг","пятница","суббота","воскресенье")) | G37: =IF(COUNTA(E37:F37)=0,"",SUM(E37:F37)) | J37: =IF(COUNTA(H37:I37)=0,"",SUM(H37:I37)) | N37: =IF(OR(C37="Ирина",C37="Обе"),Настройки!$B$3+IF(G37="",0,G37)*Настройки!$C$3,0) -> 0 | O37: =IF(OR(C37="Татьяна",C37="Обе"),Настройки!$B$4+IF(J37="",0,J37)*Настройки!$C$4,0) -> 0 | Q37: =IF(A37="","",D37+E37+H37+L37-K37-P37-M37) | S37: =IF(ISNUMBER(R37),R37-Q37,"") | T37: =IF(ISNUMBER(S37),IF(S37=0,"✅ ВСЁ ТОЧНО",IF(S37<0,"❌ НЕДОСТАЧА "&TEXT(ABS(S37),"#,##0")&" ₽","⚠️ ИЗЛИШЕК "&TEXT(S37,"#,##0")&" ₽")),"") | V37: =IF(OR(A37="",C37="",R36=""),"",IF(D37=R36,"✅ ОК","⚠️ ПРОВЕРИТЬ"))
B38: =IF(A38="","",CHOOSE(WEEKDAY(A38,2),"понедельник","вторник","среда","четверг","пятница","суббота","воскресенье")) | G38: =IF(COUNTA(E38:F38)=0,"",SUM(E38:F38)) | J38: =IF(COUNTA(H38:I38)=0,"",SUM(H38:I38)) | N38: =IF(OR(C38="Ирина",C38="Обе"),Настройки!$B$3+IF(G38="",0,G38)*Настройки!$C$3,0) -> 0 | O38: =IF(OR(C38="Татьяна",C38="Обе"),Настройки!$B$4+IF(J38="",0,J38)*Настройки!$C$4,0) -> 0 | Q38: =IF(A38="","",D38+E38+H38+L38-K38-P38-M38) | S38: =IF(ISNUMBER(R38),R38-Q38,"") | T38: =IF(ISNUMBER(S38),IF(S38=0,"✅ ВСЁ ТОЧНО",IF(S38<0,"❌ НЕДОСТАЧА "&TEXT(ABS(S38),"#,##0")&" ₽","⚠️ ИЗЛИШЕК "&TEXT(S38,"#,##0")&" ₽")),"") | V38: =IF(OR(A38="",C38="",R37=""),"",IF(D38=R37,"✅ ОК","⚠️ ПРОВЕРИТЬ"))
B39: =IF(A39="","",CHOOSE(WEEKDAY(A39,2),"понедельник","вторник","среда","четверг","пятница","суббота","воскресенье")) | G39: =IF(COUNTA(E39:F39)=0,"",SUM(E39:F39)) | J39: =IF(COUNTA(H39:I39)=0,"",SUM(H39:I39)) | N39: =IF(OR(C39="Ирина",C39="Обе"),Настройки!$B$3+IF(G39="",0,G39)*Настройки!$C$3,0) -> 0 | O39: =IF(OR(C39="Татьяна",C39="Обе"),Настройки!$B$4+IF(J39="",0,J39)*Настройки!$C$4,0) -> 0 | Q39: =IF(A39="","",D39+E39+H39+L39-K39-P39-M39) | S39: =IF(ISNUMBER(R39),R39-Q39,"") | T39: =IF(ISNUMBER(S39),IF(S39=0,"✅ ВСЁ ТОЧНО",IF(S39<0,"❌ НЕДОСТАЧА "&TEXT(ABS(S39),"#,##0")&" ₽","⚠️ ИЗЛИШЕК "&TEXT(S39,"#,##0")&" ₽")),"") | V39: =IF(OR(A39="",C39="",R38=""),"",IF(D39=R38,"✅ ОК","⚠️ ПРОВЕРИТЬ"))
B40: =IF(A40="","",CHOOSE(WEEKDAY(A40,2),"понедельник","вторник","среда","четверг","пятница","суббота","воскресенье")) | G40: =IF(COUNTA(E40:F40)=0,"",SUM(E40:F40)) | J40: =IF(COUNTA(H40:I40)=0,"",SUM(H40:I40)) | N40: =IF(OR(C40="Ирина",C40="Обе"),Настройки!$B$3+IF(G40="",0,G40)*Настройки!$C$3,0) -> 0 | O40: =IF(OR(C40="Татьяна",C40="Обе"),Настройки!$B$4+IF(J40="",0,J40)*Настройки!$C$4,0) -> 0 | Q40: =IF(A40="","",D40+E40+H40+L40-K40-P40-M40) | S40: =IF(ISNUMBER(R40),R40-Q40,"") | T40: =IF(ISNUMBER(S40),IF(S40=0,"✅ ВСЁ ТОЧНО",IF(S40<0,"❌ НЕДОСТАЧА "&TEXT(ABS(S40),"#,##0")&" ₽","⚠️ ИЗЛИШЕК "&TEXT(S40,"#,##0")&" ₽")),"") | V40: =IF(OR(A40="",C40="",R39=""),"",IF(D40=R39,"✅ ОК","⚠️ ПРОВЕРИТЬ"))
B41: =IF(A41="","",CHOOSE(WEEKDAY(A41,2),"понедельник","вторник","среда","четверг","пятница","суббота","воскресенье")) | G41: =IF(COUNTA(E41:F41)=0,"",SUM(E41:F41)) | J41: =IF(COUNTA(H41:I41)=0,"",SUM(H41:I41)) | N41: =IF(OR(C41="Ирина",C41="Обе"),Настройки!$B$3+IF(G41="",0,G41)*Настройки!$C$3,0) -> 0 | O41: =IF(OR(C41="Татьяна",C41="Обе"),Настройки!$B$4+IF(J41="",0,J41)*Настройки!$C$4,0) -> 0 | Q41: =IF(A41="","",D41+E41+H41+L41-K41-P41-M41) | S41: =IF(ISNUMBER(R41),R41-Q41,"") | T41: =IF(ISNUMBER(S41),IF(S41=0,"✅ ВСЁ ТОЧНО",IF(S41<0,"❌ НЕДОСТАЧА "&TEXT(ABS(S41),"#,##0")&" ₽","⚠️ ИЗЛИШЕК "&TEXT(S41,"#,##0")&" ₽")),"") | V41: =IF(OR(A41="",C41="",R40=""),"",IF(D41=R40,"✅ ОК","⚠️ ПРОВЕРИТЬ"))
B42: =IF(A42="","",CHOOSE(WEEKDAY(A42,2),"понедельник","вторник","среда","четверг","пятница","суббота","воскресенье")) | G42: =IF(COUNTA(E42:F42)=0,"",SUM(E42:F42)) | J42: =IF(COUNTA(H42:I42)=0,"",SUM(H42:I42)) | N42: =IF(OR(C42="Ирина",C42="Обе"),Настройки!$B$3+IF(G42="",0,G42)*Настройки!$C$3,0) -> 0 | O42: =IF(OR(C42="Татьяна",C42="Обе"),Настройки!$B$4+IF(J42="",0,J42)*Настройки!$C$4,0) -> 0 | Q42: =IF(A42="","",D42+E42+H42+L42-K42-P42-M42) | S42: =IF(ISNUMBER(R42),R42-Q42,"") | T42: =IF(ISNUMBER(S42),IF(S42=0,"✅ ВСЁ ТОЧНО",IF(S42<0,"❌ НЕДОСТАЧА "&TEXT(ABS(S42),"#,##0")&" ₽","⚠️ ИЗЛИШЕК "&TEXT(S42,"#,##0")&" ₽")),"") | V42: =IF(OR(A42="",C42="",R41=""),"",IF(D42=R41,"✅ ОК","⚠️ ПРОВЕРИТЬ"))
B43: =IF(A43="","",CHOOSE(WEEKDAY(A43,2),"понедельник","вторник","среда","четверг","пятница","суббота","воскресенье")) | G43: =IF(COUNTA(E43:F43)=0,"",SUM(E43:F43)) | J43: =IF(COUNTA(H43:I43)=0,"",SUM(H43:I43)) | N43: =IF(OR(C43="Ирина",C43="Обе"),Настройки!$B$3+IF(G43="",0,G43)*Настройки!$C$3,0) -> 0 | O43: =IF(OR(C43="Татьяна",C43="Обе"),Настройки!$B$4+IF(J43="",0,J43)*Настройки!$C$4,0) -> 0 | Q43: =IF(A43="","",D43+E43+H43+L43-K43-P43-M43) | S43: =IF(ISNUMBER(R43),R43-Q43,"") | T43: =IF(ISNUMBER(S43),IF(S43=0,"✅ ВСЁ ТОЧНО",IF(S43<0,"❌ НЕДОСТАЧА "&TEXT(ABS(S43),"#,##0")&" ₽","⚠️ ИЗЛИШЕК "&TEXT(S43,"#,##0")&" ₽")),"") | V43: =IF(OR(A43="",C43="",R42=""),"",IF(D43=R42,"✅ ОК","⚠️ ПРОВЕРИТЬ"))
...

Sheet Отчеты
A1: ОТЧЁТ ПО КАССЕ И ПРОДАЖАМ
A2: Период | B2: 46266 | C2: 46295
A4: Показатель | B4: Ирина | C4: Татьяна | D4: ВСЕГО | E4: Что смотреть каждый день
A5: Рабочих смен | B5: =COUNTIFS(Касса!$C$4:$C$102,"Ирина",Касса!$A$4:$A$102,">="&$B$2,Касса!$A$4:$A$102,"<="&$C$2)+COUNTIFS(Касса!$C$4:$C$102,"Обе",Касса!$A$4:$A$102,">="&$B$2,Касса!$A$4:$A$102,"<="&$C$2) -> 0 | C5: =COUNTIFS(Касса!$C$4:$C$102,"Татьяна",Касса!$A$4:$A$102,">="&$B$2,Касса!$A$4:$A$102,"<="&$C$2)+COUNTIFS(Касса!$C$4:$C$102,"Обе",Касса!$A$4:$A$102,">="&$B$2,Касса!$A$4:$A$102,"<="&$C$2) -> 0 | D5: =B5+C5 -> 0 | E5: 1 | F5: Фактический остаток вечером | G5: вносите вручную | H5: колонка R
A6: Выручка нал | B6: =SUMIFS(Касса!$E$4:$E$102,Касса!$A$4:$A$102,">="&$B$2,Касса!$A$4:$A$102,"<="&$C$2) -> 0 | C6: =SUMIFS(Касса!$H$4:$H$102,Касса!$A$4:$A$102,">="&$B$2,Касса!$A$4:$A$102,"<="&$C$2) -> 0 | D6: =B6+C6 -> 0 | E6: 2 | F6: Разница | G6: Факт − Расчёт | H6: колонка S
A7: Выручка безнал | B7: =SUMIFS(Касса!$F$4:$F$102,Касса!$A$4:$A$102,">="&$B$2,Касса!$A$4:$A$102,"<="&$C$2) -> 0 | C7: =SUMIFS(Касса!$I$4:$I$102,Касса!$A$4:$A$102,">="&$B$2,Касса!$A$4:$A$102,"<="&$C$2) -> 0 | D7: =B7+C7 -> 0 | E7: 3 | F7: Статус | G7: НЕДОСТАЧА / ИЗЛИШЕК | H7: колонка T
A8: ОБЩАЯ ВЫРУЧКА | B8: =B6+B7 -> 0 | C8: =C6+C7 -> 0 | D8: =D6+D7 -> 0 | E8: 4 | F8: Продажи | G8: сверяйте наличку и безнал | H8: E/F и H/I
A9: ЗП начислено | B9: =SUMIFS(Касса!$N$4:$N$102,Касса!$A$4:$A$102,">="&$B$2,Касса!$A$4:$A$102,"<="&$C$2) -> 0 | C9: =SUMIFS(Касса!$O$4:$O$102,Касса!$A$4:$A$102,">="&$B$2,Касса!$A$4:$A$102,"<="&$C$2) -> 0 | D9: =B9+C9 -> 0 | E9: 5 | F9: Расходы | G9: только из кассы | H9: K
E10: 6 | F10: Выданная ЗП | G10: только если реально выдали из кассы | H10: P
A11: КОНТРОЛЬ КАССЫ | B11: Значение
A12: Расходы из кассы | B12: =SUMIFS(Касса!$K$4:$K$102,Касса!$A$4:$A$102,">="&$B$2,Касса!$A$4:$A$102,"<="&$C$2) -> 0 | E12: Важно: отрицательная разница = фактическая наличка ниже расчётной. Это сигнал для проверки чеков, возвратов, расходов и внесений, а не доказательство хищения. 16.09 расход 30 950 ₽ снят как неподтверждённый; внесения 6 120 ₽ и 5 700 ₽ отмечены как требующие подтверждения. 01.09 имеет отдельную недостачу 30 356 ₽ — её нужно сверить по фактическому остатку/операциям этого дня.
A13: Внесено доп. в кассу | B13: =SUMIFS(Касса!$L$4:$L$102,Касса!$A$4:$A$102,">="&$B$2,Касса!$A$4:$A$102,"<="&$C$2) -> 0
A14: Изъято из кассы | B14: =SUMIFS(Касса!$M$4:$M$102,Касса!$A$4:$A$102,">="&$B$2,Касса!$A$4:$A$102,"<="&$C$2) -> 0
A15: ЗП выдано из кассы | B15: =SUMIFS(Касса!$P$4:$P$102,Касса!$A$4:$A$102,">="&$B$2,Касса!$A$4:$A$102,"<="&$C$2) -> 0
A16: ВСЕГО НЕДОСТАЧА | B16: =-SUMIFS(Касса!$S$4:$S$102,Касса!$A$4:$A$102,">="&$B$2,Касса!$A$4:$A$102,"<="&$C$2,Касса!$S$4:$S$102,"<0") -> 0
A17: ВСЕГО ИЗЛИШЕК | B17: =SUMIFS(Касса!$S$4:$S$102,Касса!$A$4:$A$102,">="&$B$2,Касса!$A$4:$A$102,"<="&$C$2,Касса!$S$4:$S$102,">0") -> 0
A18: ДНЕЙ С НЕДОСТАЧЕЙ | B18: =COUNTIFS(Касса!$S$4:$S$102,"<0",Касса!$A$4:$A$102,">="&$B$2,Касса!$A$4:$A$102,"<="&$C$2) -> 0
A19: Средняя недостача | B19: =IF(B18=0,0,B16/B18) -> 0
A20: ПРОВЕРОК УТРОМ | B20: =COUNTIFS(Касса!$V$4:$V$102,"⚠️ ПРОВЕРИТЬ",Касса!$A$4:$A$102,">="&$B$2,Касса!$A$4:$A$102,"<="&$C$2) -> 0
A21: Дата | B21: Разница | C21: Смена
A22: =IFERROR(IF(AND(Касса!#REF!>=$B$2,Касса!#REF!<=$C$2),Касса!#REF!,""),"") | B22: =IF(A22="","",IFERROR(Касса!#REF!,"")) | C22: =IF(A22="","",IFERROR(Касса!#REF!,""))
A23: =IFERROR(IF(AND(Касса!A4>=$B$2,Касса!A4<=$C$2),Касса!A4,""),"") | B23: =IF(A23="","",IFERROR(Касса!S4,"")) | C23: =IF(A23="","",IFERROR(Касса!C4,""))
A24: =IFERROR(IF(AND(Касса!A5>=$B$2,Касса!A5<=$C$2),Касса!A5,""),"") | B24: =IF(A24="","",IFERROR(Касса!S5,"")) | C24: =IF(A24="","",IFERROR(Касса!C5,""))
A25: =IFERROR(IF(AND(Касса!A6>=$B$2,Касса!A6<=$C$2),Касса!A6,""),"") | B25: =IF(A25="","",IFERROR(Касса!S6,"")) | C25: =IF(A25="","",IFERROR(Касса!C6,""))
A26: =IFERROR(IF(AND(Касса!A7>=$B$2,Касса!A7<=$C$2),Касса!A7,""),"") | B26: =IF(A26="","",IFERROR(Касса!S7,"")) | C26: =IF(A26="","",IFERROR(Касса!C7,""))
A27: =IFERROR(IF(AND(Касса!A8>=$B$2,Касса!A8<=$C$2),Касса!A8,""),"") | B27: =IF(A27="","",IFERROR(Касса!S8,"")) | C27: =IF(A27="","",IFERROR(Касса!C8,""))
A28: =IFERROR(IF(AND(Касса!A9>=$B$2,Касса!A9<=$C$2),Касса!A9,""),"") | B28: =IF(A28="","",IFERROR(Касса!S9,"")) | C28: =IF(A28="","",IFERROR(Касса!C9,""))
A29: =IFERROR(IF(AND(Касса!A10>=$B$2,Касса!A10<=$C$2),Касса!A10,""),"") | B29: =IF(A29="","",IFERROR(Касса!S10,"")) | C29: =IF(A29="","",IFERROR(Касса!C10,""))
A30: =IFERROR(IF(AND(Касса!A11>=$B$2,Касса!A11<=$C$2),Касса!A11,""),"") | B30: =IF(A30="","",IFERROR(Касса!S11,"")) | C30: =IF(A30="","",IFERROR(Касса!C11,""))
A31: =IFERROR(IF(AND(Касса!A12>=$B$2,Касса!A12<=$C$2),Касса!A12,""),"") | B31: =IF(A31="","",IFERROR(Касса!S12,"")) | C31: =IF(A31="","",IFERROR(Касса!C12,""))
A32: =IFERROR(IF(AND(Касса!A13>=$B$2,Касса!A13<=$C$2),Касса!A13,""),"") | B32: =IF(A32="","",IFERROR(Касса!S13,"")) | C32: =IF(A32="","",IFERROR(Касса!C13,""))
A33: =IFERROR(IF(AND(Касса!A14>=$B$2,Касса!A14<=$C$2),Касса!A14,""),"") | B33: =IF(A33="","",IFERROR(Касса!S14,"")) | C33: =IF(A33="","",IFERROR(Касса!C14,""))
A34: =IFERROR(IF(AND(Касса!A15>=$B$2,Касса!A15<=$C$2),Касса!A15,""),"") | B34: =IF(A34="","",IFERROR(Касса!S15,"")) | C34: =IF(A34="","",IFERROR(Касса!C15,""))
... A52: =IFERROR(IF(AND(Касса!A33>=$B$2,Касса!A33<=$C$2),Касса!A33,""),"") | B52: =IF(A52="","",IFERROR(Касса!S33,"")) | C52: =IF(A52="","",IFERROR(Касса!C33,""))
